[2025-04-22 13:18:52] INFO in evaluate (evaluate.py:172): Start evaluate 5 HDR.
[2025-04-22 13:19:23] INFO in evaluate (evaluate.py:178): Successfully evaluate 5/5 HDR.
[2025-04-22 13:19:23] INFO in se_evo (se_evo.py:321): Start trial 2025-04-22 13:19:23.959827
[2025-04-22 13:19:23] INFO in se_evo (se_evo.py:323): Init phase
[2025-04-22 13:19:48] INFO in evaluate (evaluate.py:331): Start evaluate 26 HDR.
[2025-04-22 13:20:10] INFO in evaluate (evaluate.py:344): Successfully evaluate 26/26 HDR.
[2025-04-22 13:20:10] INFO in se_evo (se_evo.py:335): FE = 26, best HDR with fitness 95.00
[2025-04-22 13:20:10] INFO in se_evo (se_evo.py:339): Gen 1:
[2025-04-22 13:20:10] INFO in se_evo (se_evo.py:345): Success select 10 inds from population with size 26
[2025-04-22 13:20:28] ERROR in se_evo (se_evo.py:449): <class 'llm.BadResponseException'>:Bad response:
{
    "results": [

nes. Multiplying by 
Traceback (most recent call last):
  File "F:\SeEvoDJSSP\llm.py", line 251, in extract_response
    json_obj = json.loads(json_str)
  File "C:\Users\admin\AppData\Local\Programs\Python\Python313\Lib\json\__init__.py", line 346, in loads
    return _default_decoder.decode(s)
           ~~~~~~~~~~~~~~~~~~~~~~~^^^
  File "C:\Users\admin\AppData\Local\Programs\Python\Python313\Lib\json\decoder.py", line 345, in decode
    obj, end = self.raw_decode(s, idx=_w(s, 0).end())
               ~~~~~~~~~~~~~~~^^^^^^^^^^^^^^^^^^^^^^^
  File "C:\Users\admin\AppData\Local\Programs\Python\Python313\Lib\json\decoder.py", line 361, in raw_decode
    obj, end = self.scan_once(s, idx)
               ~~~~~~~~~~~~~~^^^^^^^^
json.decoder.JSONDecodeError: Unterminated string starting at: line 14 column 27 (char 1487)

During handling of the above exception, another exception occurred:

Traceback (most recent call last):
  File "F:\SeEvoDJSSP\se_evo.py", line 348, in se_evo
    S_r_inds = co_evo_func(S_p.inds)
  File "F:\SeEvoDJSSP\se_evo.py", line 138, in __call__
    return super().__call__(inds=inds)
           ~~~~~~~~~~~~~~~~^^^^^^^^^^^
  File "F:\SeEvoDJSSP\se_evo.py", line 53, in __call__
    json_repsonse = self.llm_model.extract_response(response)
  File "F:\SeEvoDJSSP\llm.py", line 255, in extract_response
    raise BadResponseException(msg="Bad response:" + json_str[:20] + "\n" + json_str[-20:])
llm.BadResponseException
[2025-04-22 13:20:28] WARNING in se_evo (se_evo.py:450): Num gen still 1
[2025-04-22 13:20:28] INFO in se_evo (se_evo.py:339): Gen 1:
[2025-04-22 13:20:28] INFO in se_evo (se_evo.py:345): Success select 10 inds from population with size 26
[2025-04-22 13:20:46] ERROR in se_evo (se_evo.py:449): <class 'llm.BadResponseException'>:Bad response:
{
    "results": [

ble modification is 
Traceback (most recent call last):
  File "F:\SeEvoDJSSP\llm.py", line 251, in extract_response
    json_obj = json.loads(json_str)
  File "C:\Users\admin\AppData\Local\Programs\Python\Python313\Lib\json\__init__.py", line 346, in loads
    return _default_decoder.decode(s)
           ~~~~~~~~~~~~~~~~~~~~~~~^^^
  File "C:\Users\admin\AppData\Local\Programs\Python\Python313\Lib\json\decoder.py", line 345, in decode
    obj, end = self.raw_decode(s, idx=_w(s, 0).end())
               ~~~~~~~~~~~~~~~^^^^^^^^^^^^^^^^^^^^^^^
  File "C:\Users\admin\AppData\Local\Programs\Python\Python313\Lib\json\decoder.py", line 361, in raw_decode
    obj, end = self.scan_once(s, idx)
               ~~~~~~~~~~~~~~^^^^^^^^
json.decoder.JSONDecodeError: Unterminated string starting at: line 10 column 27 (char 863)

During handling of the above exception, another exception occurred:

Traceback (most recent call last):
  File "F:\SeEvoDJSSP\se_evo.py", line 348, in se_evo
    S_r_inds = co_evo_func(S_p.inds)
  File "F:\SeEvoDJSSP\se_evo.py", line 138, in __call__
    return super().__call__(inds=inds)
           ~~~~~~~~~~~~~~~~^^^^^^^^^^^
  File "F:\SeEvoDJSSP\se_evo.py", line 53, in __call__
    json_repsonse = self.llm_model.extract_response(response)
  File "F:\SeEvoDJSSP\llm.py", line 255, in extract_response
    raise BadResponseException(msg="Bad response:" + json_str[:20] + "\n" + json_str[-20:])
llm.BadResponseException
[2025-04-22 13:20:46] WARNING in se_evo (se_evo.py:450): Num gen still 1
[2025-04-22 13:20:46] INFO in se_evo (se_evo.py:339): Gen 1:
[2025-04-22 13:20:46] INFO in se_evo (se_evo.py:345): Success select 10 inds from population with size 26
[2025-04-22 13:21:03] INFO in se_evo (se_evo.py:350): Successfully co-evo with 10 inds
[2025-04-22 13:21:21] ERROR in se_evo (se_evo.py:449): <class 'llm.BadResponseException'>:Bad response:
{
    "recombined_h
 urgency"},
    ]
}
Traceback (most recent call last):
  File "F:\SeEvoDJSSP\llm.py", line 251, in extract_response
    json_obj = json.loads(json_str)
  File "C:\Users\admin\AppData\Local\Programs\Python\Python313\Lib\json\__init__.py", line 346, in loads
    return _default_decoder.decode(s)
           ~~~~~~~~~~~~~~~~~~~~~~~^^^
  File "C:\Users\admin\AppData\Local\Programs\Python\Python313\Lib\json\decoder.py", line 345, in decode
    obj, end = self.raw_decode(s, idx=_w(s, 0).end())
               ~~~~~~~~~~~~~~~^^^^^^^^^^^^^^^^^^^^^^^
  File "C:\Users\admin\AppData\Local\Programs\Python\Python313\Lib\json\decoder.py", line 361, in raw_decode
    obj, end = self.scan_once(s, idx)
               ~~~~~~~~~~~~~~^^^^^^^^
json.decoder.JSONDecodeError: Illegal trailing comma before end of array: line 5 column 485 (char 1016)

During handling of the above exception, another exception occurred:

Traceback (most recent call last):
  File "F:\SeEvoDJSSP\se_evo.py", line 362, in se_evo
    off1, off2 = llm_crossover_func(p1=p1, p2=p2)
                 ~~~~~~~~~~~~~~~~~~^^^^^^^^^^^^^^
  File "F:\SeEvoDJSSP\se_evo.py", line 172, in __call__
    return super().__call__(p1=p1, p2=p2)
           ~~~~~~~~~~~~~~~~^^^^^^^^^^^^^^
  File "F:\SeEvoDJSSP\se_evo.py", line 53, in __call__
    json_repsonse = self.llm_model.extract_response(response)
  File "F:\SeEvoDJSSP\llm.py", line 255, in extract_response
    raise BadResponseException(msg="Bad response:" + json_str[:20] + "\n" + json_str[-20:])
llm.BadResponseException
[2025-04-22 13:21:21] WARNING in se_evo (se_evo.py:450): Num gen still 1
[2025-04-22 13:21:21] INFO in se_evo (se_evo.py:339): Gen 1:
[2025-04-22 13:21:21] INFO in se_evo (se_evo.py:345): Success select 10 inds from population with size 26
[2025-04-22 13:21:37] ERROR in se_evo (se_evo.py:449): <class 'llm.BadResponseException'>:Bad response:
{
    "results": [

erhaps by weighting 
Traceback (most recent call last):
  File "F:\SeEvoDJSSP\llm.py", line 251, in extract_response
    json_obj = json.loads(json_str)
  File "C:\Users\admin\AppData\Local\Programs\Python\Python313\Lib\json\__init__.py", line 346, in loads
    return _default_decoder.decode(s)
           ~~~~~~~~~~~~~~~~~~~~~~~^^^
  File "C:\Users\admin\AppData\Local\Programs\Python\Python313\Lib\json\decoder.py", line 345, in decode
    obj, end = self.raw_decode(s, idx=_w(s, 0).end())
               ~~~~~~~~~~~~~~~^^^^^^^^^^^^^^^^^^^^^^^
  File "C:\Users\admin\AppData\Local\Programs\Python\Python313\Lib\json\decoder.py", line 361, in raw_decode
    obj, end = self.scan_once(s, idx)
               ~~~~~~~~~~~~~~^^^^^^^^
json.decoder.JSONDecodeError: Unterminated string starting at: line 6 column 27 (char 271)

During handling of the above exception, another exception occurred:

Traceback (most recent call last):
  File "F:\SeEvoDJSSP\se_evo.py", line 348, in se_evo
    S_r_inds = co_evo_func(S_p.inds)
  File "F:\SeEvoDJSSP\se_evo.py", line 138, in __call__
    return super().__call__(inds=inds)
           ~~~~~~~~~~~~~~~~^^^^^^^^^^^
  File "F:\SeEvoDJSSP\se_evo.py", line 53, in __call__
    json_repsonse = self.llm_model.extract_response(response)
  File "F:\SeEvoDJSSP\llm.py", line 255, in extract_response
    raise BadResponseException(msg="Bad response:" + json_str[:20] + "\n" + json_str[-20:])
llm.BadResponseException
[2025-04-22 13:21:37] WARNING in se_evo (se_evo.py:450): Num gen still 1
[2025-04-22 13:21:37] INFO in se_evo (se_evo.py:339): Gen 1:
[2025-04-22 13:21:37] INFO in se_evo (se_evo.py:345): Success select 10 inds from population with size 26
