[2025-04-19 23:01:49] INFO in se_evo (se_evo.py:320): Start trial 2025-04-19 23:01:49.420595
[2025-04-19 23:01:49] INFO in se_evo (se_evo.py:322): Init phase
[2025-04-19 23:01:51] ERROR in se_evo (se_evo.py:329): <class 'llm.BadAPIException'>:Rate limit exceeded: free-models-per-day. Add 10 credits to unlock 1000 free model requests per day
Traceback (most recent call last):
  File "F:\SeEvoDJSSP\se_evo.py", line 325, in se_evo
    P: Population = llm_init_func(init_size=init_size,
                    ~~~~~~~~~~~~~^^^^^^^^^^^^^^^^^^^^^
                              func_template=get_template(template_file_path))
                              ^^^^^^^^^^^^^^^^^^^^^^^^^^^^^^^^^^^^^^^^^^^^^^^
  File "F:\SeEvoDJSSP\se_evo.py", line 83, in __call__
    return super().__call__(init_size=init_size, func_template=func_template)
           ~~~~~~~~~~~~~~~~^^^^^^^^^^^^^^^^^^^^^^^^^^^^^^^^^^^^^^^^^^^^^^^^^^
  File "F:\SeEvoDJSSP\se_evo.py", line 51, in __call__
    response = self.llm_model.get_response(prompt)
  File "F:\SeEvoDJSSP\llm.py", line 164, in get_response
    raise BadAPIException(msg=response.json()['error']['message'])
llm.BadAPIException
[2025-04-19 23:11:55] INFO in se_evo (se_evo.py:320): Start trial 2025-04-19 23:11:55.379338
[2025-04-19 23:11:55] INFO in se_evo (se_evo.py:322): Init phase
[2025-04-19 23:11:55] ERROR in se_evo (se_evo.py:329): <class 'llm.BadAPIException'>:400 Client Error: Bad Request for url: https://generativelanguage.googleapis.com/v1beta2/models/gemini-2.0-flash-lite:generateText?key=AIzaSyBkPvOFY0OnNAKthnQQb2Tqs6PVR3kKI6A
Traceback (most recent call last):
  File "F:\SeEvoDJSSP\llm.py", line 223, in get_response
    resp.raise_for_status()
    ~~~~~~~~~~~~~~~~~~~~~^^
  File "C:\Users\admin\AppData\Local\Programs\Python\Python313\Lib\site-packages\requests\models.py", line 1024, in raise_for_status
    raise HTTPError(http_error_msg, response=self)
requests.exceptions.HTTPError: 400 Client Error: Bad Request for url: https://generativelanguage.googleapis.com/v1beta2/models/gemini-2.0-flash-lite:generateText?key=AIzaSyBkPvOFY0OnNAKthnQQb2Tqs6PVR3kKI6A

During handling of the above exception, another exception occurred:

Traceback (most recent call last):
  File "F:\SeEvoDJSSP\se_evo.py", line 325, in se_evo
    P: Population = llm_init_func(init_size=init_size,
                    ~~~~~~~~~~~~~^^^^^^^^^^^^^^^^^^^^^
                              func_template=get_template(template_file_path))
                              ^^^^^^^^^^^^^^^^^^^^^^^^^^^^^^^^^^^^^^^^^^^^^^^
  File "F:\SeEvoDJSSP\se_evo.py", line 83, in __call__
    return super().__call__(init_size=init_size, func_template=func_template)
           ~~~~~~~~~~~~~~~~^^^^^^^^^^^^^^^^^^^^^^^^^^^^^^^^^^^^^^^^^^^^^^^^^^
  File "F:\SeEvoDJSSP\se_evo.py", line 51, in __call__
    response = self.llm_model.get_response(prompt)
  File "F:\SeEvoDJSSP\llm.py", line 233, in get_response
    raise BadAPIException(str(e))
llm.BadAPIException
[2025-04-19 23:12:17] INFO in se_evo (se_evo.py:320): Start trial 2025-04-19 23:12:17.478110
[2025-04-19 23:12:17] INFO in se_evo (se_evo.py:322): Init phase
[2025-04-19 23:12:18] ERROR in se_evo (se_evo.py:329): <class 'llm.BadAPIException'>:400 Client Error: Bad Request for url: https://generativelanguage.googleapis.com/v1beta2/models/gemini-2.0-flash:generateText?key=AIzaSyBkPvOFY0OnNAKthnQQb2Tqs6PVR3kKI6A
Traceback (most recent call last):
  File "F:\SeEvoDJSSP\llm.py", line 223, in get_response
    resp.raise_for_status()
    ~~~~~~~~~~~~~~~~~~~~~^^
  File "C:\Users\admin\AppData\Local\Programs\Python\Python313\Lib\site-packages\requests\models.py", line 1024, in raise_for_status
    raise HTTPError(http_error_msg, response=self)
requests.exceptions.HTTPError: 400 Client Error: Bad Request for url: https://generativelanguage.googleapis.com/v1beta2/models/gemini-2.0-flash:generateText?key=AIzaSyBkPvOFY0OnNAKthnQQb2Tqs6PVR3kKI6A

During handling of the above exception, another exception occurred:

Traceback (most recent call last):
  File "F:\SeEvoDJSSP\se_evo.py", line 325, in se_evo
    P: Population = llm_init_func(init_size=init_size,
                    ~~~~~~~~~~~~~^^^^^^^^^^^^^^^^^^^^^
                              func_template=get_template(template_file_path))
                              ^^^^^^^^^^^^^^^^^^^^^^^^^^^^^^^^^^^^^^^^^^^^^^^
  File "F:\SeEvoDJSSP\se_evo.py", line 83, in __call__
    return super().__call__(init_size=init_size, func_template=func_template)
           ~~~~~~~~~~~~~~~~^^^^^^^^^^^^^^^^^^^^^^^^^^^^^^^^^^^^^^^^^^^^^^^^^^
  File "F:\SeEvoDJSSP\se_evo.py", line 51, in __call__
    response = self.llm_model.get_response(prompt)
  File "F:\SeEvoDJSSP\llm.py", line 233, in get_response
    raise BadAPIException(str(e))
llm.BadAPIException
[2025-04-19 23:13:17] INFO in se_evo (se_evo.py:320): Start trial 2025-04-19 23:13:17.135027
[2025-04-19 23:13:17] INFO in se_evo (se_evo.py:322): Init phase
[2025-04-19 23:13:18] ERROR in se_evo (se_evo.py:329): <class 'llm.BadAPIException'>:400 Client Error: Bad Request for url: https://generativelanguage.googleapis.com/v1beta/models/gemini-2.0-flash:generateContent?key=AIzaSyBkPvOFY0OnNAKthnQQb2Tqs6PVR3kKI6A
Traceback (most recent call last):
  File "F:\SeEvoDJSSP\llm.py", line 223, in get_response
    resp.raise_for_status()
    ~~~~~~~~~~~~~~~~~~~~~^^
  File "C:\Users\admin\AppData\Local\Programs\Python\Python313\Lib\site-packages\requests\models.py", line 1024, in raise_for_status
    raise HTTPError(http_error_msg, response=self)
requests.exceptions.HTTPError: 400 Client Error: Bad Request for url: https://generativelanguage.googleapis.com/v1beta/models/gemini-2.0-flash:generateContent?key=AIzaSyBkPvOFY0OnNAKthnQQb2Tqs6PVR3kKI6A

During handling of the above exception, another exception occurred:

Traceback (most recent call last):
  File "F:\SeEvoDJSSP\se_evo.py", line 325, in se_evo
    P: Population = llm_init_func(init_size=init_size,
                    ~~~~~~~~~~~~~^^^^^^^^^^^^^^^^^^^^^
                              func_template=get_template(template_file_path))
                              ^^^^^^^^^^^^^^^^^^^^^^^^^^^^^^^^^^^^^^^^^^^^^^^
  File "F:\SeEvoDJSSP\se_evo.py", line 83, in __call__
    return super().__call__(init_size=init_size, func_template=func_template)
           ~~~~~~~~~~~~~~~~^^^^^^^^^^^^^^^^^^^^^^^^^^^^^^^^^^^^^^^^^^^^^^^^^^
  File "F:\SeEvoDJSSP\se_evo.py", line 51, in __call__
    response = self.llm_model.get_response(prompt)
  File "F:\SeEvoDJSSP\llm.py", line 233, in get_response
    raise BadAPIException(str(e))
llm.BadAPIException
[2025-04-19 23:18:31] INFO in se_evo (se_evo.py:320): Start trial 2025-04-19 23:18:31.779289
[2025-04-19 23:18:31] INFO in se_evo (se_evo.py:322): Init phase
[2025-04-19 23:18:44] ERROR in se_evo (se_evo.py:329): <class 'llm.BadResponseException'>:Failed to parse JSON: Expecting value: line 1 column 1 (char 0)
Traceback (most recent call last):
  File "F:\SeEvoDJSSP\llm.py", line 245, in extract_response
    return json.loads(response)
           ~~~~~~~~~~^^^^^^^^^^
  File "C:\Users\admin\AppData\Local\Programs\Python\Python313\Lib\json\__init__.py", line 346, in loads
    return _default_decoder.decode(s)
           ~~~~~~~~~~~~~~~~~~~~~~~^^^
  File "C:\Users\admin\AppData\Local\Programs\Python\Python313\Lib\json\decoder.py", line 345, in decode
    obj, end = self.raw_decode(s, idx=_w(s, 0).end())
               ~~~~~~~~~~~~~~~^^^^^^^^^^^^^^^^^^^^^^^
  File "C:\Users\admin\AppData\Local\Programs\Python\Python313\Lib\json\decoder.py", line 363, in raw_decode
    raise JSONDecodeError("Expecting value", s, err.value) from None
json.decoder.JSONDecodeError: Expecting value: line 1 column 1 (char 0)

During handling of the above exception, another exception occurred:

Traceback (most recent call last):
  File "F:\SeEvoDJSSP\se_evo.py", line 325, in se_evo
    P: Population = llm_init_func(init_size=init_size,
                    ~~~~~~~~~~~~~^^^^^^^^^^^^^^^^^^^^^
                              func_template=get_template(template_file_path))
                              ^^^^^^^^^^^^^^^^^^^^^^^^^^^^^^^^^^^^^^^^^^^^^^^
  File "F:\SeEvoDJSSP\se_evo.py", line 83, in __call__
    return super().__call__(init_size=init_size, func_template=func_template)
           ~~~~~~~~~~~~~~~~^^^^^^^^^^^^^^^^^^^^^^^^^^^^^^^^^^^^^^^^^^^^^^^^^^
  File "F:\SeEvoDJSSP\se_evo.py", line 52, in __call__
    json_repsonse = self.llm_model.extract_response(response)
  File "F:\SeEvoDJSSP\llm.py", line 247, in extract_response
    raise BadResponseException(f"Failed to parse JSON: {e}")
llm.BadResponseException
[2025-04-19 23:19:37] INFO in se_evo (se_evo.py:320): Start trial 2025-04-19 23:19:37.619043
[2025-04-19 23:19:37] INFO in se_evo (se_evo.py:322): Init phase
[2025-04-19 23:19:51] ERROR in se_evo (se_evo.py:329): <class 'llm.BadResponseException'>:Failed to parse JSON: Expecting value: line 1 column 1 (char 0)
Traceback (most recent call last):
  File "F:\SeEvoDJSSP\llm.py", line 246, in extract_response
    return json.loads(response)
           ~~~~~~~~~~^^^^^^^^^^
  File "C:\Users\admin\AppData\Local\Programs\Python\Python313\Lib\json\__init__.py", line 346, in loads
    return _default_decoder.decode(s)
           ~~~~~~~~~~~~~~~~~~~~~~~^^^
  File "C:\Users\admin\AppData\Local\Programs\Python\Python313\Lib\json\decoder.py", line 345, in decode
    obj, end = self.raw_decode(s, idx=_w(s, 0).end())
               ~~~~~~~~~~~~~~~^^^^^^^^^^^^^^^^^^^^^^^
  File "C:\Users\admin\AppData\Local\Programs\Python\Python313\Lib\json\decoder.py", line 363, in raw_decode
    raise JSONDecodeError("Expecting value", s, err.value) from None
json.decoder.JSONDecodeError: Expecting value: line 1 column 1 (char 0)

During handling of the above exception, another exception occurred:

Traceback (most recent call last):
  File "F:\SeEvoDJSSP\se_evo.py", line 325, in se_evo
    P: Population = llm_init_func(init_size=init_size,
                    ~~~~~~~~~~~~~^^^^^^^^^^^^^^^^^^^^^
                              func_template=get_template(template_file_path))
                              ^^^^^^^^^^^^^^^^^^^^^^^^^^^^^^^^^^^^^^^^^^^^^^^
  File "F:\SeEvoDJSSP\se_evo.py", line 83, in __call__
    return super().__call__(init_size=init_size, func_template=func_template)
           ~~~~~~~~~~~~~~~~^^^^^^^^^^^^^^^^^^^^^^^^^^^^^^^^^^^^^^^^^^^^^^^^^^
  File "F:\SeEvoDJSSP\se_evo.py", line 52, in __call__
    json_repsonse = self.llm_model.extract_response(response)
  File "F:\SeEvoDJSSP\llm.py", line 248, in extract_response
    raise BadResponseException(f"Failed to parse JSON: {e}")
llm.BadResponseException
[2025-04-19 23:20:44] INFO in se_evo (se_evo.py:320): Start trial 2025-04-19 23:20:44.542768
[2025-04-19 23:20:44] INFO in se_evo (se_evo.py:322): Init phase
[2025-04-19 23:20:57] INFO in evaluate (evaluate.py:329): Start evaluate 20 HDR.
[2025-04-19 23:21:11] INFO in evaluate (evaluate.py:342): Successfully evaluate 20/20 HDR.
[2025-04-19 23:21:11] INFO in se_evo (se_evo.py:334): FE = 20, best HDR with fitness 95.00
[2025-04-19 23:21:11] INFO in se_evo (se_evo.py:338): Gen 1:
[2025-04-19 23:21:11] INFO in se_evo (se_evo.py:344): Success select 8 inds from population with size 20
[2025-04-19 23:21:21] ERROR in se_evo (se_evo.py:448): <class 'llm.BadResponseException'>:Bad response:
{
    "results": [

l contribution from 
Traceback (most recent call last):
  File "F:\SeEvoDJSSP\llm.py", line 249, in extract_response
    json_obj = json.loads(json_str)
  File "C:\Users\admin\AppData\Local\Programs\Python\Python313\Lib\json\__init__.py", line 346, in loads
    return _default_decoder.decode(s)
           ~~~~~~~~~~~~~~~~~~~~~~~^^^
  File "C:\Users\admin\AppData\Local\Programs\Python\Python313\Lib\json\decoder.py", line 345, in decode
    obj, end = self.raw_decode(s, idx=_w(s, 0).end())
               ~~~~~~~~~~~~~~~^^^^^^^^^^^^^^^^^^^^^^^
  File "C:\Users\admin\AppData\Local\Programs\Python\Python313\Lib\json\decoder.py", line 361, in raw_decode
    obj, end = self.scan_once(s, idx)
               ~~~~~~~~~~~~~~^^^^^^^^
json.decoder.JSONDecodeError: Unterminated string starting at: line 10 column 27 (char 1018)

During handling of the above exception, another exception occurred:

Traceback (most recent call last):
  File "F:\SeEvoDJSSP\se_evo.py", line 347, in se_evo
    S_r_inds = co_evo_func(S_p.inds)
  File "F:\SeEvoDJSSP\se_evo.py", line 137, in __call__
    return super().__call__(inds=inds)
           ~~~~~~~~~~~~~~~~^^^^^^^^^^^
  File "F:\SeEvoDJSSP\se_evo.py", line 52, in __call__
    json_repsonse = self.llm_model.extract_response(response)
  File "F:\SeEvoDJSSP\llm.py", line 253, in extract_response
    raise BadResponseException(msg="Bad response:" + json_str[:20] + "\n" + json_str[-20:])
llm.BadResponseException
[2025-04-19 23:21:21] WARNING in se_evo (se_evo.py:449): Num gen still 1
[2025-04-19 23:21:21] INFO in se_evo (se_evo.py:338): Gen 1:
[2025-04-19 23:21:21] INFO in se_evo (se_evo.py:344): Success select 8 inds from population with size 20
[2025-04-19 23:21:30] INFO in se_evo (se_evo.py:349): Successfully co-evo with 8 inds
[2025-04-19 23:21:41] INFO in se_evo (se_evo.py:375): Successfully crossover with 8 inds
[2025-04-19 23:21:41] INFO in evaluate (evaluate.py:329): Start evaluate 8 HDR.
[2025-04-19 23:21:49] INFO in evaluate (evaluate.py:342): Successfully evaluate 8/8 HDR.
[2025-04-19 23:21:49] INFO in se_evo (se_evo.py:383): FE = 28, best HDR with fitness 90.00
[2025-04-19 23:21:57] INFO in se_evo (se_evo.py:388): Successfully self-evo with 8 inds
[2025-04-19 23:22:00] ERROR in se_evo (se_evo.py:165): :Invalid kwargs duplicate argument 'jwt' in function definition (<string>, line 1)
Traceback (most recent call last):
  File "F:\SeEvoDJSSP\model.py", line 81, in execute
    exec(self._code, globals(), local_vars)
    ~~~~^^^^^^^^^^^^^^^^^^^^^^^^^^^^^^^^^^^
  File "<string>", line 1
SyntaxError: duplicate argument 'jwt' in function definition

During handling of the above exception, another exception occurred:

Traceback (most recent call last):
  File "F:\SeEvoDJSSP\se_evo.py", line 160, in _process_json_response
    new_hdr = CodeSegmentHDR(code=code_json['code'])
  File "F:\SeEvoDJSSP\model.py", line 27, in __init__
    self.code = code
    ^^^^^^^^^
  File "F:\SeEvoDJSSP\model.py", line 39, in code
    res = self.execute(jnpt=1.0, japt=2.5, jrt=3.6, jro=4.1, jwt=6.7, jat=6.0, jd=8.0, jcd=3.0, js=2.0, jw=1.0, ml=89.0, mr=20.0, mrel=20.0, mpr=20.1, mutil=3.9, tnow=15, util=60, avgwt=20.0)
  File "F:\SeEvoDJSSP\model.py", line 87, in execute
    raise InvalidKwargsException(f"Invalid kwargs " + str(e))
model.InvalidKwargsException
[2025-04-19 23:22:10] INFO in se_evo (se_evo.py:404): Successfully crossover with 8 inds
[2025-04-19 23:22:10] INFO in evaluate (evaluate.py:329): Start evaluate 8 HDR.
[2025-04-19 23:22:16] INFO in evaluate (evaluate.py:342): Successfully evaluate 8/8 HDR.
[2025-04-19 23:22:16] INFO in se_evo (se_evo.py:410): FE = 36, best HDR with fitness 85.00
[2025-04-19 23:22:17] INFO in se_evo (se_evo.py:416): Successfully collective reflections from 16 reflections
[2025-04-19 23:22:17] INFO in se_evo (se_evo.py:433): Successfully mutation 0 inds of 8 inds
[2025-04-19 23:22:17] INFO in evaluate (evaluate.py:329): Start evaluate 8 HDR.
[2025-04-19 23:22:24] INFO in evaluate (evaluate.py:342): Successfully evaluate 8/8 HDR.
[2025-04-19 23:22:24] INFO in se_evo (se_evo.py:444): FE = 44, best HDR with fitness 95.00
[2025-04-19 23:22:24] INFO in se_evo (se_evo.py:445): Save best HDR to best/best_0.py
[2025-04-19 23:22:24] INFO in se_evo (se_evo.py:338): Gen 2:
[2025-04-19 23:22:24] INFO in se_evo (se_evo.py:344): Success select 8 inds from population with size 20
[2025-04-19 23:22:33] ERROR in se_evo (se_evo.py:448): <class 'llm.BadResponseException'>:Bad response:
{
    "results": [

ible reflection is: 
Traceback (most recent call last):
  File "F:\SeEvoDJSSP\llm.py", line 249, in extract_response
    json_obj = json.loads(json_str)
  File "C:\Users\admin\AppData\Local\Programs\Python\Python313\Lib\json\__init__.py", line 346, in loads
    return _default_decoder.decode(s)
           ~~~~~~~~~~~~~~~~~~~~~~~^^^
  File "C:\Users\admin\AppData\Local\Programs\Python\Python313\Lib\json\decoder.py", line 345, in decode
    obj, end = self.raw_decode(s, idx=_w(s, 0).end())
               ~~~~~~~~~~~~~~~^^^^^^^^^^^^^^^^^^^^^^^
  File "C:\Users\admin\AppData\Local\Programs\Python\Python313\Lib\json\decoder.py", line 361, in raw_decode
    obj, end = self.scan_once(s, idx)
               ~~~~~~~~~~~~~~^^^^^^^^
json.decoder.JSONDecodeError: Unterminated string starting at: line 6 column 27 (char 286)

During handling of the above exception, another exception occurred:

Traceback (most recent call last):
  File "F:\SeEvoDJSSP\se_evo.py", line 347, in se_evo
    S_r_inds = co_evo_func(S_p.inds)
  File "F:\SeEvoDJSSP\se_evo.py", line 137, in __call__
    return super().__call__(inds=inds)
           ~~~~~~~~~~~~~~~~^^^^^^^^^^^
  File "F:\SeEvoDJSSP\se_evo.py", line 52, in __call__
    json_repsonse = self.llm_model.extract_response(response)
  File "F:\SeEvoDJSSP\llm.py", line 253, in extract_response
    raise BadResponseException(msg="Bad response:" + json_str[:20] + "\n" + json_str[-20:])
llm.BadResponseException
[2025-04-19 23:22:33] WARNING in se_evo (se_evo.py:449): Num gen still 2
[2025-04-19 23:22:33] INFO in se_evo (se_evo.py:338): Gen 2:
[2025-04-19 23:22:33] INFO in se_evo (se_evo.py:344): Success select 8 inds from population with size 20
[2025-04-19 23:22:43] INFO in se_evo (se_evo.py:349): Successfully co-evo with 8 inds
[2025-04-19 23:22:57] INFO in se_evo (se_evo.py:375): Successfully crossover with 8 inds
[2025-04-19 23:22:57] INFO in evaluate (evaluate.py:329): Start evaluate 8 HDR.
[2025-04-19 23:23:05] INFO in evaluate (evaluate.py:342): Successfully evaluate 8/8 HDR.
[2025-04-19 23:23:05] INFO in se_evo (se_evo.py:383): FE = 52, best HDR with fitness 90.00
[2025-04-19 23:23:17] ERROR in se_evo (se_evo.py:448): <class 'llm.BadResponseException'>:Bad response:
{
    "reflected_hd
ce the influence of 
Traceback (most recent call last):
  File "F:\SeEvoDJSSP\llm.py", line 249, in extract_response
    json_obj = json.loads(json_str)
  File "C:\Users\admin\AppData\Local\Programs\Python\Python313\Lib\json\__init__.py", line 346, in loads
    return _default_decoder.decode(s)
           ~~~~~~~~~~~~~~~~~~~~~~~^^^
  File "C:\Users\admin\AppData\Local\Programs\Python\Python313\Lib\json\decoder.py", line 345, in decode
    obj, end = self.raw_decode(s, idx=_w(s, 0).end())
               ~~~~~~~~~~~~~~~^^^^^^^^^^^^^^^^^^^^^^^
  File "C:\Users\admin\AppData\Local\Programs\Python\Python313\Lib\json\decoder.py", line 361, in raw_decode
    obj, end = self.scan_once(s, idx)
               ~~~~~~~~~~~~~~^^^^^^^^
json.decoder.JSONDecodeError: Unterminated string starting at: line 18 column 27 (char 3236)

During handling of the above exception, another exception occurred:

Traceback (most recent call last):
  File "F:\SeEvoDJSSP\se_evo.py", line 386, in se_evo
    I_rm_inds = self_evo_func(compare_hdrs=compare_hdrs)
  File "F:\SeEvoDJSSP\se_evo.py", line 216, in __call__
    return super().__call__(compare_hdrs=compare_hdrs)
           ~~~~~~~~~~~~~~~~^^^^^^^^^^^^^^^^^^^^^^^^^^^
  File "F:\SeEvoDJSSP\se_evo.py", line 52, in __call__
    json_repsonse = self.llm_model.extract_response(response)
  File "F:\SeEvoDJSSP\llm.py", line 253, in extract_response
    raise BadResponseException(msg="Bad response:" + json_str[:20] + "\n" + json_str[-20:])
llm.BadResponseException
[2025-04-19 23:23:17] WARNING in se_evo (se_evo.py:449): Num gen still 2
[2025-04-19 23:23:17] INFO in se_evo (se_evo.py:338): Gen 2:
[2025-04-19 23:23:17] INFO in se_evo (se_evo.py:344): Success select 8 inds from population with size 20
[2025-04-19 23:23:26] INFO in se_evo (se_evo.py:349): Successfully co-evo with 8 inds
[2025-04-19 23:23:36] INFO in se_evo (se_evo.py:375): Successfully crossover with 8 inds
[2025-04-19 23:23:36] INFO in evaluate (evaluate.py:329): Start evaluate 8 HDR.
[2025-04-19 23:23:44] INFO in evaluate (evaluate.py:342): Successfully evaluate 8/8 HDR.
[2025-04-19 23:23:44] INFO in se_evo (se_evo.py:383): FE = 60, best HDR with fitness 92.00
[2025-04-19 23:23:55] ERROR in se_evo (se_evo.py:448): <class 'llm.BadResponseException'>:Bad response:
{
    "reflected_hd
al, merely dividing 
Traceback (most recent call last):
  File "F:\SeEvoDJSSP\llm.py", line 249, in extract_response
    json_obj = json.loads(json_str)
  File "C:\Users\admin\AppData\Local\Programs\Python\Python313\Lib\json\__init__.py", line 346, in loads
    return _default_decoder.decode(s)
           ~~~~~~~~~~~~~~~~~~~~~~~^^^
  File "C:\Users\admin\AppData\Local\Programs\Python\Python313\Lib\json\decoder.py", line 345, in decode
    obj, end = self.raw_decode(s, idx=_w(s, 0).end())
               ~~~~~~~~~~~~~~~^^^^^^^^^^^^^^^^^^^^^^^
  File "C:\Users\admin\AppData\Local\Programs\Python\Python313\Lib\json\decoder.py", line 361, in raw_decode
    obj, end = self.scan_once(s, idx)
               ~~~~~~~~~~~~~~^^^^^^^^
json.decoder.JSONDecodeError: Unterminated string starting at: line 10 column 27 (char 1201)

During handling of the above exception, another exception occurred:

Traceback (most recent call last):
  File "F:\SeEvoDJSSP\se_evo.py", line 386, in se_evo
    I_rm_inds = self_evo_func(compare_hdrs=compare_hdrs)
  File "F:\SeEvoDJSSP\se_evo.py", line 216, in __call__
    return super().__call__(compare_hdrs=compare_hdrs)
           ~~~~~~~~~~~~~~~~^^^^^^^^^^^^^^^^^^^^^^^^^^^
  File "F:\SeEvoDJSSP\se_evo.py", line 52, in __call__
    json_repsonse = self.llm_model.extract_response(response)
  File "F:\SeEvoDJSSP\llm.py", line 253, in extract_response
    raise BadResponseException(msg="Bad response:" + json_str[:20] + "\n" + json_str[-20:])
llm.BadResponseException
[2025-04-19 23:23:55] WARNING in se_evo (se_evo.py:449): Num gen still 2
[2025-04-19 23:23:55] INFO in se_evo (se_evo.py:338): Gen 2:
[2025-04-19 23:23:55] INFO in se_evo (se_evo.py:344): Success select 8 inds from population with size 20
[2025-04-19 23:24:02] INFO in se_evo (se_evo.py:349): Successfully co-evo with 8 inds
[2025-04-19 23:24:15] INFO in se_evo (se_evo.py:375): Successfully crossover with 8 inds
[2025-04-19 23:24:15] INFO in evaluate (evaluate.py:329): Start evaluate 8 HDR.
[2025-04-19 23:24:23] INFO in evaluate (evaluate.py:342): Successfully evaluate 8/8 HDR.
[2025-04-19 23:24:23] INFO in se_evo (se_evo.py:383): FE = 68, best HDR with fitness 90.00
[2025-04-19 23:24:34] ERROR in se_evo (se_evo.py:448): <class 'llm.BadResponseException'>:Bad response:
{
    "reflected_hd
zation. Introducing 
Traceback (most recent call last):
  File "F:\SeEvoDJSSP\llm.py", line 249, in extract_response
    json_obj = json.loads(json_str)
  File "C:\Users\admin\AppData\Local\Programs\Python\Python313\Lib\json\__init__.py", line 346, in loads
    return _default_decoder.decode(s)
           ~~~~~~~~~~~~~~~~~~~~~~~^^^
  File "C:\Users\admin\AppData\Local\Programs\Python\Python313\Lib\json\decoder.py", line 345, in decode
    obj, end = self.raw_decode(s, idx=_w(s, 0).end())
               ~~~~~~~~~~~~~~~^^^^^^^^^^^^^^^^^^^^^^^
  File "C:\Users\admin\AppData\Local\Programs\Python\Python313\Lib\json\decoder.py", line 361, in raw_decode
    obj, end = self.scan_once(s, idx)
               ~~~~~~~~~~~~~~^^^^^^^^
json.decoder.JSONDecodeError: Unterminated string starting at: line 5 column 240 (char 981)

During handling of the above exception, another exception occurred:

Traceback (most recent call last):
  File "F:\SeEvoDJSSP\se_evo.py", line 386, in se_evo
    I_rm_inds = self_evo_func(compare_hdrs=compare_hdrs)
  File "F:\SeEvoDJSSP\se_evo.py", line 216, in __call__
    return super().__call__(compare_hdrs=compare_hdrs)
           ~~~~~~~~~~~~~~~~^^^^^^^^^^^^^^^^^^^^^^^^^^^
  File "F:\SeEvoDJSSP\se_evo.py", line 52, in __call__
    json_repsonse = self.llm_model.extract_response(response)
  File "F:\SeEvoDJSSP\llm.py", line 253, in extract_response
    raise BadResponseException(msg="Bad response:" + json_str[:20] + "\n" + json_str[-20:])
llm.BadResponseException
[2025-04-19 23:24:34] WARNING in se_evo (se_evo.py:449): Num gen still 2
[2025-04-19 23:24:34] INFO in se_evo (se_evo.py:338): Gen 2:
[2025-04-19 23:24:34] INFO in se_evo (se_evo.py:344): Success select 8 inds from population with size 20
[2025-04-19 23:28:17] INFO in se_evo (se_evo.py:320): Start trial 2025-04-19 23:28:17.280149
[2025-04-19 23:28:17] INFO in se_evo (se_evo.py:322): Init phase
[2025-04-19 23:28:31] INFO in evaluate (evaluate.py:329): Start evaluate 20 HDR.
[2025-04-19 23:28:45] INFO in evaluate (evaluate.py:342): Successfully evaluate 20/20 HDR.
[2025-04-19 23:28:45] INFO in se_evo (se_evo.py:334): FE = 20, best HDR with fitness 85.00
[2025-04-19 23:28:45] INFO in se_evo (se_evo.py:338): Gen 1:
[2025-04-19 23:28:45] INFO in se_evo (se_evo.py:344): Success select 8 inds from population with size 20
[2025-04-19 23:28:53] INFO in se_evo (se_evo.py:349): Successfully co-evo with 8 inds
[2025-04-19 23:29:05] INFO in se_evo (se_evo.py:375): Successfully crossover with 8 inds
[2025-04-19 23:29:05] INFO in evaluate (evaluate.py:329): Start evaluate 8 HDR.
[2025-04-19 23:29:12] INFO in evaluate (evaluate.py:342): Successfully evaluate 8/8 HDR.
[2025-04-19 23:29:12] INFO in se_evo (se_evo.py:383): FE = 28, best HDR with fitness 85.00
[2025-04-19 23:29:21] INFO in se_evo (se_evo.py:388): Successfully self-evo with 8 inds
[2025-04-19 23:29:34] INFO in se_evo (se_evo.py:404): Successfully crossover with 8 inds
[2025-04-19 23:29:34] INFO in evaluate (evaluate.py:329): Start evaluate 8 HDR.
[2025-04-19 23:29:41] INFO in evaluate (evaluate.py:342): Successfully evaluate 8/8 HDR.
[2025-04-19 23:29:41] INFO in se_evo (se_evo.py:410): FE = 36, best HDR with fitness 85.00
[2025-04-19 23:29:44] INFO in se_evo (se_evo.py:416): Successfully collective reflections from 16 reflections
[2025-04-19 23:29:50] INFO in se_evo (se_evo.py:433): Successfully mutation 2 inds of 8 inds
[2025-04-19 23:29:50] INFO in evaluate (evaluate.py:329): Start evaluate 8 HDR.
[2025-04-19 23:29:59] INFO in evaluate (evaluate.py:342): Successfully evaluate 8/8 HDR.
[2025-04-19 23:29:59] INFO in se_evo (se_evo.py:444): FE = 44, best HDR with fitness 85.00
[2025-04-19 23:29:59] INFO in se_evo (se_evo.py:445): Save best HDR to best/best_0.py
[2025-04-19 23:29:59] INFO in se_evo (se_evo.py:338): Gen 2:
[2025-04-19 23:29:59] INFO in se_evo (se_evo.py:344): Success select 8 inds from population with size 20
[2025-04-19 23:30:14] ERROR in se_evo (se_evo.py:448): <class 'llm.BadResponseException'>:Bad response:
{
    "results": [

eighted difference: 
Traceback (most recent call last):
  File "F:\SeEvoDJSSP\llm.py", line 249, in extract_response
    json_obj = json.loads(json_str)
  File "C:\Users\admin\AppData\Local\Programs\Python\Python313\Lib\json\__init__.py", line 346, in loads
    return _default_decoder.decode(s)
           ~~~~~~~~~~~~~~~~~~~~~~~^^^
  File "C:\Users\admin\AppData\Local\Programs\Python\Python313\Lib\json\decoder.py", line 345, in decode
    obj, end = self.raw_decode(s, idx=_w(s, 0).end())
               ~~~~~~~~~~~~~~~^^^^^^^^^^^^^^^^^^^^^^^
  File "C:\Users\admin\AppData\Local\Programs\Python\Python313\Lib\json\decoder.py", line 361, in raw_decode
    obj, end = self.scan_once(s, idx)
               ~~~~~~~~~~~~~~^^^^^^^^
json.decoder.JSONDecodeError: Unterminated string starting at: line 6 column 27 (char 277)

During handling of the above exception, another exception occurred:

Traceback (most recent call last):
  File "F:\SeEvoDJSSP\se_evo.py", line 347, in se_evo
    S_r_inds = co_evo_func(S_p.inds)
  File "F:\SeEvoDJSSP\se_evo.py", line 137, in __call__
    return super().__call__(inds=inds)
           ~~~~~~~~~~~~~~~~^^^^^^^^^^^
  File "F:\SeEvoDJSSP\se_evo.py", line 52, in __call__
    json_repsonse = self.llm_model.extract_response(response)
  File "F:\SeEvoDJSSP\llm.py", line 253, in extract_response
    raise BadResponseException(msg="Bad response:" + json_str[:20] + "\n" + json_str[-20:])
llm.BadResponseException
[2025-04-19 23:30:14] WARNING in se_evo (se_evo.py:449): Num gen still 2
[2025-04-19 23:30:14] INFO in se_evo (se_evo.py:338): Gen 2:
[2025-04-19 23:30:14] INFO in se_evo (se_evo.py:344): Success select 8 inds from population with size 20
[2025-04-19 23:30:26] ERROR in se_evo (se_evo.py:448): <class 'llm.BadResponseException'>:Bad response:
{
    "results": [

elated factors like 
Traceback (most recent call last):
  File "F:\SeEvoDJSSP\llm.py", line 249, in extract_response
    json_obj = json.loads(json_str)
  File "C:\Users\admin\AppData\Local\Programs\Python\Python313\Lib\json\__init__.py", line 346, in loads
    return _default_decoder.decode(s)
           ~~~~~~~~~~~~~~~~~~~~~~~^^^
  File "C:\Users\admin\AppData\Local\Programs\Python\Python313\Lib\json\decoder.py", line 345, in decode
    obj, end = self.raw_decode(s, idx=_w(s, 0).end())
               ~~~~~~~~~~~~~~~^^^^^^^^^^^^^^^^^^^^^^^
  File "C:\Users\admin\AppData\Local\Programs\Python\Python313\Lib\json\decoder.py", line 361, in raw_decode
    obj, end = self.scan_once(s, idx)
               ~~~~~~~~~~~~~~^^^^^^^^
json.decoder.JSONDecodeError: Unterminated string starting at: line 30 column 27 (char 6203)

During handling of the above exception, another exception occurred:

Traceback (most recent call last):
  File "F:\SeEvoDJSSP\se_evo.py", line 347, in se_evo
    S_r_inds = co_evo_func(S_p.inds)
  File "F:\SeEvoDJSSP\se_evo.py", line 137, in __call__
    return super().__call__(inds=inds)
           ~~~~~~~~~~~~~~~~^^^^^^^^^^^
  File "F:\SeEvoDJSSP\se_evo.py", line 52, in __call__
    json_repsonse = self.llm_model.extract_response(response)
  File "F:\SeEvoDJSSP\llm.py", line 253, in extract_response
    raise BadResponseException(msg="Bad response:" + json_str[:20] + "\n" + json_str[-20:])
llm.BadResponseException
[2025-04-19 23:30:26] WARNING in se_evo (se_evo.py:449): Num gen still 2
[2025-04-19 23:30:26] INFO in se_evo (se_evo.py:338): Gen 2:
[2025-04-19 23:30:26] INFO in se_evo (se_evo.py:344): Success select 8 inds from population with size 20
[2025-04-19 23:30:39] ERROR in se_evo (se_evo.py:448): <class 'llm.BadResponseException'>:Bad response:
{
    "results": [

a quantity (perhaps 
Traceback (most recent call last):
  File "F:\SeEvoDJSSP\llm.py", line 249, in extract_response
    json_obj = json.loads(json_str)
  File "C:\Users\admin\AppData\Local\Programs\Python\Python313\Lib\json\__init__.py", line 346, in loads
    return _default_decoder.decode(s)
           ~~~~~~~~~~~~~~~~~~~~~~~^^^
  File "C:\Users\admin\AppData\Local\Programs\Python\Python313\Lib\json\decoder.py", line 345, in decode
    obj, end = self.raw_decode(s, idx=_w(s, 0).end())
               ~~~~~~~~~~~~~~~^^^^^^^^^^^^^^^^^^^^^^^
  File "C:\Users\admin\AppData\Local\Programs\Python\Python313\Lib\json\decoder.py", line 361, in raw_decode
    obj, end = self.scan_once(s, idx)
               ~~~~~~~~~~~~~~^^^^^^^^
json.decoder.JSONDecodeError: Unterminated string starting at: line 6 column 27 (char 1187)

During handling of the above exception, another exception occurred:

Traceback (most recent call last):
  File "F:\SeEvoDJSSP\se_evo.py", line 347, in se_evo
    S_r_inds = co_evo_func(S_p.inds)
  File "F:\SeEvoDJSSP\se_evo.py", line 137, in __call__
    return super().__call__(inds=inds)
           ~~~~~~~~~~~~~~~~^^^^^^^^^^^
  File "F:\SeEvoDJSSP\se_evo.py", line 52, in __call__
    json_repsonse = self.llm_model.extract_response(response)
  File "F:\SeEvoDJSSP\llm.py", line 253, in extract_response
    raise BadResponseException(msg="Bad response:" + json_str[:20] + "\n" + json_str[-20:])
llm.BadResponseException
[2025-04-19 23:30:39] WARNING in se_evo (se_evo.py:449): Num gen still 2
[2025-04-19 23:30:39] INFO in se_evo (se_evo.py:338): Gen 2:
[2025-04-19 23:30:39] INFO in se_evo (se_evo.py:344): Success select 8 inds from population with size 20
[2025-04-19 23:30:50] INFO in se_evo (se_evo.py:349): Successfully co-evo with 8 inds
[2025-04-19 23:31:04] INFO in se_evo (se_evo.py:375): Successfully crossover with 8 inds
[2025-04-19 23:31:04] INFO in evaluate (evaluate.py:329): Start evaluate 8 HDR.
[2025-04-19 23:31:13] INFO in evaluate (evaluate.py:342): Successfully evaluate 8/8 HDR.
[2025-04-19 23:31:13] INFO in se_evo (se_evo.py:383): FE = 52, best HDR with fitness 90.00
[2025-04-19 23:31:23] ERROR in se_evo (se_evo.py:448): <class 'llm.BadResponseException'>:Bad response:
{
    "reflected_hd
kespan. Introducing 
Traceback (most recent call last):
  File "F:\SeEvoDJSSP\llm.py", line 249, in extract_response
    json_obj = json.loads(json_str)
  File "C:\Users\admin\AppData\Local\Programs\Python\Python313\Lib\json\__init__.py", line 346, in loads
    return _default_decoder.decode(s)
           ~~~~~~~~~~~~~~~~~~~~~~~^^^
  File "C:\Users\admin\AppData\Local\Programs\Python\Python313\Lib\json\decoder.py", line 345, in decode
    obj, end = self.raw_decode(s, idx=_w(s, 0).end())
               ~~~~~~~~~~~~~~~^^^^^^^^^^^^^^^^^^^^^^^
  File "C:\Users\admin\AppData\Local\Programs\Python\Python313\Lib\json\decoder.py", line 361, in raw_decode
    obj, end = self.scan_once(s, idx)
               ~~~~~~~~~~~~~~^^^^^^^^
json.decoder.JSONDecodeError: Unterminated string starting at: line 10 column 27 (char 900)

During handling of the above exception, another exception occurred:

Traceback (most recent call last):
  File "F:\SeEvoDJSSP\se_evo.py", line 386, in se_evo
    I_rm_inds = self_evo_func(compare_hdrs=compare_hdrs)
  File "F:\SeEvoDJSSP\se_evo.py", line 216, in __call__
    return super().__call__(compare_hdrs=compare_hdrs)
           ~~~~~~~~~~~~~~~~^^^^^^^^^^^^^^^^^^^^^^^^^^^
  File "F:\SeEvoDJSSP\se_evo.py", line 52, in __call__
    json_repsonse = self.llm_model.extract_response(response)
  File "F:\SeEvoDJSSP\llm.py", line 253, in extract_response
    raise BadResponseException(msg="Bad response:" + json_str[:20] + "\n" + json_str[-20:])
llm.BadResponseException
[2025-04-19 23:31:23] WARNING in se_evo (se_evo.py:449): Num gen still 2
[2025-04-19 23:31:23] INFO in se_evo (se_evo.py:338): Gen 2:
[2025-04-19 23:31:23] INFO in se_evo (se_evo.py:344): Success select 8 inds from population with size 20
[2025-04-19 23:31:36] ERROR in se_evo (se_evo.py:448): <class 'llm.BadResponseException'>:Bad response:
{
    "results": [

rity, even if their 
Traceback (most recent call last):
  File "F:\SeEvoDJSSP\llm.py", line 249, in extract_response
    json_obj = json.loads(json_str)
  File "C:\Users\admin\AppData\Local\Programs\Python\Python313\Lib\json\__init__.py", line 346, in loads
    return _default_decoder.decode(s)
           ~~~~~~~~~~~~~~~~~~~~~~~^^^
  File "C:\Users\admin\AppData\Local\Programs\Python\Python313\Lib\json\decoder.py", line 345, in decode
    obj, end = self.raw_decode(s, idx=_w(s, 0).end())
               ~~~~~~~~~~~~~~~^^^^^^^^^^^^^^^^^^^^^^^
  File "C:\Users\admin\AppData\Local\Programs\Python\Python313\Lib\json\decoder.py", line 361, in raw_decode
    obj, end = self.scan_once(s, idx)
               ~~~~~~~~~~~~~~^^^^^^^^
json.decoder.JSONDecodeError: Unterminated string starting at: line 14 column 27 (char 2565)

During handling of the above exception, another exception occurred:

Traceback (most recent call last):
  File "F:\SeEvoDJSSP\se_evo.py", line 347, in se_evo
    S_r_inds = co_evo_func(S_p.inds)
  File "F:\SeEvoDJSSP\se_evo.py", line 137, in __call__
    return super().__call__(inds=inds)
           ~~~~~~~~~~~~~~~~^^^^^^^^^^^
  File "F:\SeEvoDJSSP\se_evo.py", line 52, in __call__
    json_repsonse = self.llm_model.extract_response(response)
  File "F:\SeEvoDJSSP\llm.py", line 253, in extract_response
    raise BadResponseException(msg="Bad response:" + json_str[:20] + "\n" + json_str[-20:])
llm.BadResponseException
[2025-04-19 23:31:36] WARNING in se_evo (se_evo.py:449): Num gen still 2
[2025-04-19 23:31:36] INFO in se_evo (se_evo.py:338): Gen 2:
[2025-04-19 23:31:36] INFO in se_evo (se_evo.py:344): Success select 8 inds from population with size 20
[2025-04-19 23:31:47] ERROR in se_evo (se_evo.py:448): <class 'llm.BadResponseException'>:Bad response:
{
    "results": [

aling factor to the 
Traceback (most recent call last):
  File "F:\SeEvoDJSSP\llm.py", line 249, in extract_response
    json_obj = json.loads(json_str)
  File "C:\Users\admin\AppData\Local\Programs\Python\Python313\Lib\json\__init__.py", line 346, in loads
    return _default_decoder.decode(s)
           ~~~~~~~~~~~~~~~~~~~~~~~^^^
  File "C:\Users\admin\AppData\Local\Programs\Python\Python313\Lib\json\decoder.py", line 345, in decode
    obj, end = self.raw_decode(s, idx=_w(s, 0).end())
               ~~~~~~~~~~~~~~~^^^^^^^^^^^^^^^^^^^^^^^
  File "C:\Users\admin\AppData\Local\Programs\Python\Python313\Lib\json\decoder.py", line 361, in raw_decode
    obj, end = self.scan_once(s, idx)
               ~~~~~~~~~~~~~~^^^^^^^^
json.decoder.JSONDecodeError: Unterminated string starting at: line 10 column 1143 (char 4982)

During handling of the above exception, another exception occurred:

Traceback (most recent call last):
  File "F:\SeEvoDJSSP\se_evo.py", line 347, in se_evo
    S_r_inds = co_evo_func(S_p.inds)
  File "F:\SeEvoDJSSP\se_evo.py", line 137, in __call__
    return super().__call__(inds=inds)
           ~~~~~~~~~~~~~~~~^^^^^^^^^^^
  File "F:\SeEvoDJSSP\se_evo.py", line 52, in __call__
    json_repsonse = self.llm_model.extract_response(response)
  File "F:\SeEvoDJSSP\llm.py", line 253, in extract_response
    raise BadResponseException(msg="Bad response:" + json_str[:20] + "\n" + json_str[-20:])
llm.BadResponseException
[2025-04-19 23:31:47] WARNING in se_evo (se_evo.py:449): Num gen still 2
[2025-04-19 23:31:47] INFO in se_evo (se_evo.py:338): Gen 2:
[2025-04-19 23:31:47] INFO in se_evo (se_evo.py:344): Success select 8 inds from population with size 20
[2025-04-19 23:36:12] INFO in se_evo (se_evo.py:321): Start trial 2025-04-19 23:36:12.970959
[2025-04-19 23:36:12] INFO in se_evo (se_evo.py:323): Init phase
[2025-04-19 23:36:25] INFO in evaluate (evaluate.py:329): Start evaluate 20 HDR.
[2025-04-19 23:36:39] INFO in evaluate (evaluate.py:342): Successfully evaluate 20/20 HDR.
[2025-04-19 23:36:39] INFO in se_evo (se_evo.py:335): FE = 20, best HDR with fitness 85.00
[2025-04-19 23:36:39] INFO in se_evo (se_evo.py:339): Gen 1:
[2025-04-19 23:36:39] INFO in se_evo (se_evo.py:345): Success select 8 inds from population with size 20
[2025-04-19 23:36:47] ERROR in se_evo (se_evo.py:449): <class 'llm.BadResponseException'>:Bad response:
{
    "results": [

e, consider scaling 
Traceback (most recent call last):
  File "F:\SeEvoDJSSP\llm.py", line 249, in extract_response
    json_obj = json.loads(json_str)
  File "C:\Users\admin\AppData\Local\Programs\Python\Python313\Lib\json\__init__.py", line 346, in loads
    return _default_decoder.decode(s)
           ~~~~~~~~~~~~~~~~~~~~~~~^^^
  File "C:\Users\admin\AppData\Local\Programs\Python\Python313\Lib\json\decoder.py", line 345, in decode
    obj, end = self.raw_decode(s, idx=_w(s, 0).end())
               ~~~~~~~~~~~~~~~^^^^^^^^^^^^^^^^^^^^^^^
  File "C:\Users\admin\AppData\Local\Programs\Python\Python313\Lib\json\decoder.py", line 361, in raw_decode
    obj, end = self.scan_once(s, idx)
               ~~~~~~~~~~~~~~^^^^^^^^
json.decoder.JSONDecodeError: Unterminated string starting at: line 6 column 27 (char 271)

During handling of the above exception, another exception occurred:

Traceback (most recent call last):
  File "F:\SeEvoDJSSP\se_evo.py", line 348, in se_evo
    S_r_inds = co_evo_func(S_p.inds)
  File "F:\SeEvoDJSSP\se_evo.py", line 138, in __call__
    return super().__call__(inds=inds)
           ~~~~~~~~~~~~~~~~^^^^^^^^^^^
  File "F:\SeEvoDJSSP\se_evo.py", line 53, in __call__
    json_repsonse = self.llm_model.extract_response(response)
  File "F:\SeEvoDJSSP\llm.py", line 253, in extract_response
    raise BadResponseException(msg="Bad response:" + json_str[:20] + "\n" + json_str[-20:])
llm.BadResponseException
[2025-04-19 23:36:47] WARNING in se_evo (se_evo.py:450): Num gen still 1
[2025-04-19 23:37:17] INFO in se_evo (se_evo.py:339): Gen 1:
[2025-04-19 23:37:17] INFO in se_evo (se_evo.py:345): Success select 8 inds from population with size 20
[2025-04-19 23:37:26] INFO in se_evo (se_evo.py:350): Successfully co-evo with 8 inds
[2025-04-19 23:37:35] INFO in se_evo (se_evo.py:376): Successfully crossover with 8 inds
[2025-04-19 23:37:35] INFO in evaluate (evaluate.py:329): Start evaluate 8 HDR.
[2025-04-19 23:37:42] INFO in evaluate (evaluate.py:342): Successfully evaluate 8/8 HDR.
[2025-04-19 23:37:42] INFO in se_evo (se_evo.py:384): FE = 28, best HDR with fitness 90.00
[2025-04-19 23:37:51] INFO in se_evo (se_evo.py:389): Successfully self-evo with 8 inds
[2025-04-19 23:38:01] INFO in se_evo (se_evo.py:405): Successfully crossover with 8 inds
[2025-04-19 23:38:01] INFO in evaluate (evaluate.py:329): Start evaluate 8 HDR.
[2025-04-19 23:38:08] INFO in evaluate (evaluate.py:342): Successfully evaluate 8/8 HDR.
[2025-04-19 23:38:08] INFO in se_evo (se_evo.py:411): FE = 36, best HDR with fitness 90.00
[2025-04-19 23:38:09] INFO in se_evo (se_evo.py:417): Successfully collective reflections from 16 reflections
[2025-04-19 23:38:11] INFO in se_evo (se_evo.py:434): Successfully mutation 1 inds of 8 inds
[2025-04-19 23:38:11] INFO in evaluate (evaluate.py:329): Start evaluate 8 HDR.
[2025-04-19 23:38:19] INFO in evaluate (evaluate.py:342): Successfully evaluate 8/8 HDR.
[2025-04-19 23:38:19] INFO in se_evo (se_evo.py:445): FE = 44, best HDR with fitness 85.00
[2025-04-19 23:38:19] INFO in se_evo (se_evo.py:446): Save best HDR to best/best_0.py
[2025-04-19 23:38:19] INFO in se_evo (se_evo.py:339): Gen 2:
[2025-04-19 23:38:19] INFO in se_evo (se_evo.py:345): Success select 8 inds from population with size 20
[2025-04-19 23:38:27] INFO in se_evo (se_evo.py:350): Successfully co-evo with 8 inds
[2025-04-19 23:38:39] INFO in se_evo (se_evo.py:376): Successfully crossover with 8 inds
[2025-04-19 23:38:39] INFO in evaluate (evaluate.py:329): Start evaluate 8 HDR.
[2025-04-19 23:38:45] INFO in evaluate (evaluate.py:342): Successfully evaluate 8/8 HDR.
[2025-04-19 23:38:45] INFO in se_evo (se_evo.py:384): FE = 52, best HDR with fitness 85.00
[2025-04-19 23:38:53] INFO in se_evo (se_evo.py:389): Successfully self-evo with 8 inds
[2025-04-19 23:39:01] INFO in se_evo (se_evo.py:405): Successfully crossover with 8 inds
[2025-04-19 23:39:01] INFO in evaluate (evaluate.py:329): Start evaluate 8 HDR.
[2025-04-19 23:39:06] INFO in evaluate (evaluate.py:342): Successfully evaluate 8/8 HDR.
[2025-04-19 23:39:06] INFO in se_evo (se_evo.py:411): FE = 60, best HDR with fitness 90.00
[2025-04-19 23:39:08] INFO in se_evo (se_evo.py:417): Successfully collective reflections from 16 reflections
[2025-04-19 23:39:10] INFO in se_evo (se_evo.py:434): Successfully mutation 1 inds of 8 inds
[2025-04-19 23:39:10] INFO in evaluate (evaluate.py:329): Start evaluate 8 HDR.
[2025-04-19 23:39:16] INFO in evaluate (evaluate.py:342): Successfully evaluate 8/8 HDR.
[2025-04-19 23:39:16] INFO in se_evo (se_evo.py:445): FE = 68, best HDR with fitness 85.00
[2025-04-19 23:39:16] INFO in se_evo (se_evo.py:446): Save best HDR to best/best_1.py
[2025-04-19 23:39:16] INFO in se_evo (se_evo.py:339): Gen 3:
[2025-04-19 23:39:16] INFO in se_evo (se_evo.py:345): Success select 8 inds from population with size 20
[2025-04-19 23:39:25] ERROR in se_evo (se_evo.py:449): <class 'llm.BadResponseException'>:Bad response:
{
    "results": [

ailability, such as 
Traceback (most recent call last):
  File "F:\SeEvoDJSSP\llm.py", line 249, in extract_response
    json_obj = json.loads(json_str)
  File "C:\Users\admin\AppData\Local\Programs\Python\Python313\Lib\json\__init__.py", line 346, in loads
    return _default_decoder.decode(s)
           ~~~~~~~~~~~~~~~~~~~~~~~^^^
  File "C:\Users\admin\AppData\Local\Programs\Python\Python313\Lib\json\decoder.py", line 345, in decode
    obj, end = self.raw_decode(s, idx=_w(s, 0).end())
               ~~~~~~~~~~~~~~~^^^^^^^^^^^^^^^^^^^^^^^
  File "C:\Users\admin\AppData\Local\Programs\Python\Python313\Lib\json\decoder.py", line 361, in raw_decode
    obj, end = self.scan_once(s, idx)
               ~~~~~~~~~~~~~~^^^^^^^^
json.decoder.JSONDecodeError: Unterminated string starting at: line 26 column 27 (char 4225)

During handling of the above exception, another exception occurred:

Traceback (most recent call last):
  File "F:\SeEvoDJSSP\se_evo.py", line 348, in se_evo
    S_r_inds = co_evo_func(S_p.inds)
  File "F:\SeEvoDJSSP\se_evo.py", line 138, in __call__
    return super().__call__(inds=inds)
           ~~~~~~~~~~~~~~~~^^^^^^^^^^^
  File "F:\SeEvoDJSSP\se_evo.py", line 53, in __call__
    json_repsonse = self.llm_model.extract_response(response)
  File "F:\SeEvoDJSSP\llm.py", line 253, in extract_response
    raise BadResponseException(msg="Bad response:" + json_str[:20] + "\n" + json_str[-20:])
llm.BadResponseException
[2025-04-19 23:39:25] WARNING in se_evo (se_evo.py:450): Num gen still 3
